Workbook
Name 業務リスト: #REF!
Name 新宿: #REF!
Name 相続人リスト: #REF!,#REF!,#REF!,#REF!,#REF!,#REF!
Name 続柄リスト: #REF!
Name 大坂: #REF!
Name 担当: 基本情報入力!$J$71:$K$176
Name 担当者リスト: #REF!
Name 担当者情報: #REF!
Name 本店: #REF!

Sheet 基本情報入力
A1: 基本情報入力
A2: ・こちらの『基本情報入力』シートの【⒈基本情報】~【⒋被相続人・相続人 基本情報】に必要事項を入力ください
A3: ・ヒアリングシートを参考に【⒍金融機関 基本情報】と【⒎不動産 基本情報】に必要事項を入力ください
A4: ・戸籍担当へ戸籍収集等を依頼される場合、『戸籍収集引継書』の14行より下、指示部分は直接入力ください
A5: ・『送付状』『返送書類リスト』は印刷後、分けずにホチキス止めして、まとめて送付ください
A8: ⒈基本情報 | B8: ※黄色セルは必ず入力ください | F8: ⒉送付書類 | H8: 返送書類リスト記載チェック | J8: ⒊返送書類
A9: 顧客コード | C9: 登記担当 | F9: ⑴ | G9: 契約書 | I9: TRUE | J9: 印鑑証明書（原本）
A10: 顧客名 | C10: 税チェ関与 | F10: ⑵ | G10: 重要事項説明書 | I10: TRUE
A11: プラン | C11: 値引きの有無 | F11: ⑶ | G11: 相続手続き業務に関する確認事項 | I11: TRUE
A12: 拠点 | C12: 委任状の日付 | F12: ⑷ | G12: 委任状 | I12: TRUE
A13: 担当① | C13: 担当② | F13: ⑸ | G13: 口座の凍結についての確認書 | I13: TRUE
A14: 初回送付日 | C14: 提携先 | F14: ⑹ | G14: 不動産・金融機関情報一覧 | I14: TRUE
A15: 送付先1 | F15: ⑺ | G15: 戸籍関係情報 | I15: TRUE
A16: 送付先2 | F16: ⑻ | G16: 請求書 | I16: FALSE
A17: 委任状通数 | F17: ⑼ | G17: 返信用封筒(書類の返送にご使用ください) | I17: FALSE
A18: 印鑑証明書数 | F18: ⑽ | I18: FALSE
A19: 返信用封筒通数 | F19: ⑾ | I19: FALSE
A21: ⒋被相続人・相続人 基本情報
A22: 番号 | B22: 続柄 | C22: 氏名 (行政 太郎) | D22: ふりがな (ぎょうせい たろう) | E22: 生年月日 (R1.1.1) | F22: 死亡日 (R1.1.1) | G22: 〒 (000-0000) | H22: 住所1 (東京都中央区八重洲一丁目7-20) | I22: 住所2 (八重洲口会館2階) | J22: TEL (00-0000-0000) | K22: 本籍地 (東京都中央区八重洲一丁目7番20号) | L22: 筆頭者 (行政 太郎) | Q22: =IF(R22="",FALSE,TRUE) -> TRUE | R22: =J9&"" -> 印鑑証明書（原本）
A23: 被相続人 | B23: 本人 | Q23: =IF(R23="",FALSE,TRUE) -> FALSE | R23: =J10&""
A24: 相続人①(代表) | Q24: =IF(R24="",FALSE,TRUE) -> FALSE | R24: =J11&""
A25: 相続人② | Q25: =IF(R25="",FALSE,TRUE) -> FALSE | R25: =J12&""
A26: 相続人③ | Q26: =IF(R26="",FALSE,TRUE) -> FALSE | R26: =J13&""
A27: 相続人④
A28: 相続人⑤
A29: 相続人⑥
A30: 相続人⑦
A31: 相続人⑧
A32: 相続人⑨
A33: 相続人⑩
A34: 相続人⑪
A35: 相続人⑫
A37: ⒌戸籍担当
A38: 法定相続情報 | D38: 戸籍
A39: 配偶者 | D39: 対象者
A40: 相続人
A41: 相続人 | D41: 戸籍担当者
A42: 相続人 | D42: 拠点 | E42: 担当者
A43: 相続人 | D43: 東京 | E43: 増田
A46: ⒍金融機関 基本情報 | G46: ⒎不動産 基本情報
...

Sheet 戸籍収集引継書 
A1: =基本情報入力!$C$23&"" | C1: =基本情報入力!$B$9&"" | E1: =基本情報入力!$B$11&"" | G1: =基本情報入力!$D$13&""
A3: ふりがな | B3: =基本情報入力!$D$23&""
A4: 氏名 | B4: =基本情報入力!$C$23&""
A5: 最後の住所 | B5: =基本情報入力!$H$23&" "&基本情報入力!$I$23
A6: 生年月日 | B6: =IF(基本情報入力!$E$23="","",基本情報入力!$E$23)
A7: 死亡年月日 | B7: =IF(基本情報入力!$F$23="","",基本情報入力!$F$23)
A8: 本籍 | B8: =基本情報入力!$K$23&""
A9: 筆頭者 | B9: =基本情報入力!$L$23&""
A10: 委任者 | B10: =基本情報入力!$D$24&""
A11: =基本情報入力!$B$24&"" | B11: =基本情報入力!$C$24&""
A12: 取得書類
A14: □申請中 □完了 | B14: 被相続人の法定相続人確定のため 全ての戸籍除籍、戸籍の附票の収集をお願いします。 既に取得している戸籍等の原本があるものは追加取得不要です。
A15: □申請中 □完了 | B15: 住民票除票、改製原附票の収集をお願いします。
A16: □申請中 □完了 | B16: 法定相続情報の申請をお願いします。
A17: □申請中 □完了 | B17: R7年度名寄帳の取得もお願いします。（千代田区、横浜市西区、鎌倉市）
A18: □申請中 □完了
A19: 備考
B20: 相続人は妻、子供（３名）の計4名
A21: 引継ぎ前のチェックリスト
A22: 法定作成前 法定作成後 | B22: 金融機関の手続きのタイミングについて
A23: 確認済 | B23: 必要な戸籍、名寄帳等書類について通数（通常1通）、年度等を確認して、 必要な取得書類については全て上記に入力した。
A24: 確認済 | B24: 先に亡くなった親族の未手続財産がないか確認をして、 今回の被相続人に係る戸籍、名寄帳等の書類以外取得しなくてよいことを確認した。 手続きが必要な場合は、上記に必要書類を記載した。
A25: 確認済 | B25: 預り済みの戸籍類及び必要書類は原本を戸籍収集担当者へ全て渡した。
A26: 引継ぎ資料
A27: 確認済 | B27: 委任状 | C27: 3通 | D27: 確認済
A28: 確認済 | D28: 確認済
A29: 確認済 | D29: 確認済
A30: 確認済 | D30: 確認済

Sheet 送付先宛名シール
M2: ① | O2: ② | P2: 〒000-0000
B3: ="〒"&(IF(VLOOKUP(基本情報入力!$B$15,基本情報入力!$A$23:$K$35,7,FALSE)="","",VLOOKUP(基本情報入力!$B$15,基本情報入力!$A$23:$K$35,7,FALSE))) -> #N/A | G3: =$B$3 -> #N/A | M3: 【印刷レイアウト】 グレーの部分は印刷されません | P3: 東京都港区虎ノ門 0-0-0
P4: □□ビル 12F
B5: =IF(VLOOKUP(基本情報入力!$B$15,基本情報入力!$A$23:$K$35,8,FALSE)="","",VLOOKUP(基本情報入力!$B$15,基本情報入力!$A$23:$K$35,8,FALSE)) -> #N/A | G5: =$B$5 -> #N/A | P5: ピー + エスシー株式会社
B6: =IF(VLOOKUP(基本情報入力!$B$15,基本情報入力!$A$23:$K$35,9,FALSE)="","",VLOOKUP(基本情報入力!$B$15,基本情報入力!$A$23:$K$35,9,FALSE)) -> #N/A | G6: =$B$6 -> #N/A | P6: □□グループ
B7: =IF(VLOOKUP(基本情報入力!$B$15,基本情報入力!$A$23:$K$35,3,FALSE)="","",VLOOKUP(基本情報入力!$B$15,基本情報入力!$A$23:$K$35,3,FALSE))&" 様" -> #N/A | G7: =$B$7 -> #N/A | P7: 主任 高橋 直也 様
C9: ="TEL："&(IF(VLOOKUP(基本情報入力!$B$15,基本情報入力!$A$23:$K$35,10,FALSE)="","",VLOOKUP(基本情報入力!$B$15,基本情報入力!$A$23:$K$35,10,FALSE))) -> #N/A | H9: =$C$9 -> #N/A
M12: ③
B13: =$B$3 -> #N/A | G13: =$B$3 -> #N/A | N13: 編集する時の注意！ ・列の幅を変更したり、行を追加しないでください。 印刷する時の注意！ ・プリンターの印刷設定より、給紙トレイを「手差し」に、用紙種類を「ラベル・厚紙」などに変更し、必ず手差しトレイから給紙してください。 印刷の向きは、印刷面下、差し込み方向矢印と逆にセットしてください。 アレンジのポイント！ ・文字のフォント、色、背景を自由に変えられます。
B15: =$B$5 -> #N/A | G15: =$B$5 -> #N/A
B16: =$B$6 -> #N/A | G16: =$B$6 -> #N/A
B17: =$B$7 -> #N/A | G17: =$B$7 -> #N/A
C19: =$C$9 -> #N/A | H19: =$C$9 -> #N/A
B23: =$B$3 -> #N/A | G23: =$B$3 -> #N/A
B25: =$B$5 -> #N/A | G25: =$B$5 -> #N/A
B26: =$B$6 -> #N/A | G26: =$B$6 -> #N/A
B27: =$B$7 -> #N/A | G27: =$B$7 -> #N/A
C29: =$C$9 -> #N/A | H29: =$C$9 -> #N/A
B33: {="〒"&(_xlfn.IFS(基本情報入力!$B$16="",VLOOKUP(基本情報入力!$B$12,基本情報入力!$N$72:$S$107,2,FALSE),基本情報入力!$B$16<>"",VLOOKUP(基本情報入力!$B$16,基本情報入力!$A$23:$K$35,7,FALSE)))} -> #N/A | G33: =$B$33 -> #N/A
B35: {=_xlfn.IFS(基本情報入力!$B$16="",VLOOKUP(基本情報入力!$B$12,基本情報入力!$N$72:$S$107,3,FALSE),基本情報入力!$B$16<>"",VLOOKUP(基本情報入力!$B$16,基本情報入力!$A$23:$K$35,8,FALSE))} -> #N/A | G35: =$B$35 -> #N/A
B36: =IF($M$36=0,"",$M$36) -> #N/A | G36: =$B$36 -> #N/A | M36: {=_xlfn.IFS(基本情報入力!$B$16="",VLOOKUP(基本情報入力!$B$12,基本情報入力!$N$72:$S$107,4,FALSE),基本情報入力!$B$16<>"",VLOOKUP(基本情報入力!$B$16,基本情報入力!$A$23:$K$35,9,FALSE),TRUE,"")} -> #N/A
B37: {=_xlfn.IFS(基本情報入力!$B$16="","行政書士法人チェスター",基本情報入力!$B$16<>"",VLOOKUP(基本情報入力!$B$16,基本情報入力!$A$23:$K$35,3,FALSE)&" 様")} -> 行政書士法人チェスター | G37: =$B$37 -> 行政書士法人チェスター
C39: ="TEL："&(IF(基本情報入力!$B$16="",送付状!$W$12,VLOOKUP(基本情報入力!$B$16,基本情報入力!$A$23:$K$35,10,FALSE))) -> #N/A | H39: =$C$39 -> #N/A
B43: =$B$33 -> #N/A | G43: =$B$33 -> #N/A
B45: =$B$35 -> #N/A | G45: =$B$35 -> #N/A
B46: =$B$36 -> #N/A | G46: =$B$36 -> #N/A
B47: =$B$37 -> 行政書士法人チェスター | G47: =$B$37 -> 行政書士法人チェスター
C49: =$C$39 -> #N/A | H49: =$C$39 -> #N/A
B53: =$B$33 -> #N/A | G53: =$B$33 -> #N/A
B55: =$B$35 -> #N/A | G55: =$B$35 -> #N/A
B56: =$B$36 -> #N/A | G56: =$B$36 -> #N/A
B57: =$B$37 -> 行政書士法人チェスター | G57: =$B$37 -> 行政書士法人チェスター
C59: =$C$39 -> #N/A | H59: =$C$39 -> #N/A

Sheet 送付状
C2: 書類送付のご案内
V3: =基本情報入力!$B$14 -> 0
C5: =IFERROR(VLOOKUP(基本情報入力!$B$15,基本情報入力!$A$23:$K$35,3,FALSE),"")
K6: 様
T7: 行政書士法人チェスター
W8: 担当： | Y8: =基本情報入力!$B$13 -> 0
C9: 拝啓 平素は格別のご高配を賜り厚く御礼申し上げます。 | Z9: =VLOOKUP(基本情報入力!$B$12,基本情報入力!$N$71:$S$1000,2,FALSE) -> #N/A
C10: さて、本日下記の資料をお届け申し上げましたので、 | Z10: =VLOOKUP(基本情報入力!$B$12,基本情報入力!$N$71:$S$1000,3,FALSE) -> #N/A
C11: 御査収いただきますようお願い申し上げます。敬具 | Z11: =VLOOKUP(基本情報入力!$B$12,基本情報入力!$N$71:$S$1000,4,FALSE) -> #N/A
V12: TEL: | W12: =VLOOKUP(基本情報入力!$B$13,基本情報入力!$G$72:$H$1000,2,FALSE) -> #N/A
V13: FAX: | W13: =VLOOKUP(基本情報入力!$B$12,基本情報入力!$N$72:$S$1000,6,FALSE) -> #N/A
C15: 記
C17: 摘要 | W17: 通数（部数）
B18: =$D18&"" -> 契約書 | C18: =IF($D18="","",基本情報入力!$F9) -> ⑴ | D18: =IF(基本情報入力!$G9="","",基本情報入力!$G9) -> 契約書 | X18: {=_xlfn.IFS($D18="","",$D18="委任状",基本情報入力!$B$17,$D18="契約書",2,$D18="返信用封筒（書類の返送にご使用ください）",基本情報入力!$B$19,$D18="重要事項説明書",2,$D18="相続手続き業務に関する確認事項",2,TRUE,1)} -> 2 | Y18: =IF($X18="","","通") -> 通
B19: =$D19&"" -> 重要事項説明書 | C19: =IF($D19="","",基本情報入力!$F10) -> ⑵ | D19: =IF(基本情報入力!$G10="","",基本情報入力!$G10) -> 重要事項説明書 | X19: {=_xlfn.IFS($D19="","",$D19="委任状",基本情報入力!$B$17,$D19="契約書",2,$D19="返信用封筒（書類の返送にご使用ください）",基本情報入力!$B$19,$D19="重要事項説明書",2,$D19="相続手続き業務に関する確認事項",2,TRUE,1)} -> 2 | Y19: =IF($X19="","","通") -> 通
B20: =$D20&"" -> 相続手続き業務に関する確認事項 | C20: =IF($D20="","",基本情報入力!$F11) -> ⑶ | D20: =IF(基本情報入力!$G11="","",基本情報入力!$G11) -> 相続手続き業務に関する確認事項 | X20: {=_xlfn.IFS($D20="","",$D20="委任状",基本情報入力!$B$17,$D20="契約書",2,$D20="返信用封筒（書類の返送にご使用ください）",基本情報入力!$B$19,$D20="重要事項説明書",2,$D20="相続手続き業務に関する確認事項",2,TRUE,1)} -> 2 | Y20: =IF($X20="","","通") -> 通
B21: =$D21&"" -> 委任状 | C21: =IF($D21="","",基本情報入力!$F12) -> ⑷ | D21: =IF(基本情報入力!$G12="","",基本情報入力!$G12) -> 委任状 | X21: {=_xlfn.IFS($D21="","",$D21="委任状",基本情報入力!$B$17,$D21="契約書",2,$D21="返信用封筒（書類の返送にご使用ください）",基本情報入力!$B$19,$D21="重要事項説明書",2,$D21="相続手続き業務に関する確認事項",2,TRUE,1)} -> 0 | Y21: =IF($X21="","","通") -> 通
B22: =$D22&"" -> 口座の凍結についての確認書 | C22: =IF($D22="","",基本情報入力!$F13) -> ⑸ | D22: =IF(基本情報入力!$G13="","",基本情報入力!$G13) -> 口座の凍結についての確認書 | X22: {=_xlfn.IFS($D22="","",$D22="委任状",基本情報入力!$B$17,$D22="契約書",2,$D22="返信用封筒（書類の返送にご使用ください）",基本情報入力!$B$19,$D22="重要事項説明書",2,$D22="相続手続き業務に関する確認事項",2,TRUE,1)} -> 1 | Y22: =IF($X22="","","通") -> 通
B23: =$D23&"" -> 不動産・金融機関情報一覧 | C23: =IF($D23="","",基本情報入力!$F14) -> ⑹ | D23: =IF(基本情報入力!$G14="","",基本情報入力!$G14) -> 不動産・金融機関情報一覧 | X23: {=_xlfn.IFS($D23="","",$D23="委任状",基本情報入力!$B$17,$D23="契約書",2,$D23="返信用封筒（書類の返送にご使用ください）",基本情報入力!$B$19,$D23="重要事項説明書",2,$D23="相続手続き業務に関する確認事項",2,TRUE,1)} -> 1 | Y23: =IF($X23="","","通") -> 通
B24: =$D24&"" -> 戸籍関係情報 | C24: =IF($D24="","",基本情報入力!$F15) -> ⑺ | D24: =IF(基本情報入力!$G15="","",基本情報入力!$G15) -> 戸籍関係情報 | X24: {=_xlfn.IFS($D24="","",$D24="委任状",基本情報入力!$B$17,$D24="契約書",2,$D24="返信用封筒（書類の返送にご使用ください）",基本情報入力!$B$19,$D24="重要事項説明書",2,$D24="相続手続き業務に関する確認事項",2,TRUE,1)} -> 1 | Y24: =IF($X24="","","通") -> 通
B25: =$D25&"" -> 請求書 | C25: =IF($D25="","",基本情報入力!$F16) -> ⑻ | D25: =IF(基本情報入力!$G16="","",基本情報入力!$G16) -> 請求書 | X25: {=_xlfn.IFS($D25="","",$D25="委任状",基本情報入力!$B$17,$D25="契約書",2,$D25="返信用封筒（書類の返送にご使用ください）",基本情報入力!$B$19,$D25="重要事項説明書",2,$D25="相続手続き業務に関する確認事項",2,TRUE,1)} -> 1 | Y25: =IF($X25="","","通") -> 通
B26: =$D26&"" -> 返信用封筒(書類の返送にご使用ください) | C26: =IF($D26="","",基本情報入力!$F17) -> ⑼ | D26: =IF(基本情報入力!$G17="","",基本情報入力!$G17) -> 返信用封筒(書類の返送にご使用ください) | X26: {=_xlfn.IFS($D26="","",$D26="委任状",基本情報入力!$B$17,$D26="契約書",2,$D26="返信用封筒（書類の返送にご使用ください）",基本情報入力!$B$19,$D26="重要事項説明書",2,$D26="相続手続き業務に関する確認事項",2,TRUE,1)} -> 1 | Y26: =IF($X26="","","通") -> 通
B27: =$D27&"" | C27: =IF($D27="","",基本情報入力!$F18) | D27: =IF(基本情報入力!$G18="","",基本情報入力!$G18) | X27: {=_xlfn.IFS($D27="","",$D27="委任状",基本情報入力!$B$17,$D27="契約書",2,$D27="返信用封筒（書類の返送にご使用ください）",基本情報入力!$B$19,$D27="重要事項説明書",2,$D27="相続手続き業務に関する確認事項",2,TRUE,1)} | Y27: =IF($X27="","","通")
B28: =$D28&"" | C28: =IF($D28="","",基本情報入力!$F19) | D28: =IF(基本情報入力!$G19="","",基本情報入力!$G19) | X28: {=_xlfn.IFS($D28="","",$D28="委任状",基本情報入力!$B$17,$D28="契約書",2,$D28="返信用封筒（書類の返送にご使用ください）",基本情報入力!$B$19,$D28="重要事項説明書",2,$D28="相続手続き業務に関する確認事項",2,TRUE,1)} | Y28: =IF($X28="","","通")
C29: 通信欄：
C30: この度は、ご依頼いただき誠にありがとうございます。 上記書類をお送りいたしますので、お手数ではございますが、送付状２枚目(返送書類リスト)をご確認いただき、ご対応の上ご返送くださいますようお願い申し上げます。 また請求書を同封しておりますので、同書記載の期限までにお振込みのほどよろしくお願い申し上げます。 ご不明点等ございましたら、お気軽にご連絡ください。 業務完了まで、何卒よろしくお願いいたします。

Sheet 返送書類リスト
B1: 返送書類リスト | E1: =基本情報入力!$C$24&" 様" -> 様 | F1: =IFERROR(VLOOKUP($B$1,送付状!$B$18:$O$28,2,FALSE),"")
B6: 以下、⒈⒉のリストに記載のあるものを、同封の返信用封筒にて弊社へご返送願います。
B7: ⒈ 弊社からお送りした書類のうち、ご返送いただきたい書類
B8: ☑ | C8: № | D8: 名称 | E8: 詳細 | F8: 返送 通数
A9: =$D9&"" -> 契約書 | B9: =IF($F9="","","□") -> □ | C9: {=_xlfn._xlws.FILTER(基本情報入力!$F$9:$G$19,基本情報入力!$I$9:$I$19,"")} -> ⑴ | D9: 契約書 | E9: =IFERROR(VLOOKUP($D9,基本情報入力!AA$72:AB$109,2,FALSE),"") -> ご署名のうえ、1通をお手元に保管いただき、残り1通をご返送願います。 | F9: {=_xlfn.IFS($D9="委任状",基本情報入力!$B$17,$D9="","",TRUE,1)} -> 1 | G9: =IF($F9="","","通") -> 通
A10: =$D10&"" -> 重要事項説明書 | B10: =IF($F10="","","□") -> □ | C10: ⑵ | D10: 重要事項説明書 | E10: =IFERROR(VLOOKUP($D10,基本情報入力!AA$72:AB$109,2,FALSE),"") -> ご署名のうえ、1通をお手元に保管いただき、残り1通をご返送願います。 | F10: {=_xlfn.IFS($D10="委任状",基本情報入力!$B$17,$D10="","",TRUE,1)} -> 1 | G10: =IF($F10="","","通") -> 通
A11: =$D11&"" -> 相続手続き業務に関する確認事項 | B11: =IF($F11="","","□") -> □ | C11: ⑶ | D11: 相続手続き業務に関する確認事項 | E11: =IFERROR(VLOOKUP($D11,基本情報入力!AA$72:AB$109,2,FALSE),"") -> 各項目をご確認いただきチェックボックスにレ点を入れてください。全ての項目にレ点を入れ終えましたら、下部の署名欄にご署名のうえ、1通をお手元に保管いただき、残り1通をご返送願います。 | F11: {=_xlfn.IFS($D11="委任状",基本情報入力!$B$17,$D11="","",TRUE,1)} -> 1 | G11: =IF($F11="","","通") -> 通
A12: =$D12&"" -> 委任状 | B12: =IF($F12="","","□") -> □ | C12: ⑷ | D12: 委任状 | E12: =IFERROR(VLOOKUP($D12,基本情報入力!AA$72:AB$109,2,FALSE),"") -> ご署名ご捺印（実印）のうえ、ご返送願います。 | F12: {=_xlfn.IFS($D12="委任状",基本情報入力!$B$17,$D12="","",TRUE,1)} -> 0 | G12: =IF($F12="","","通") -> 通
A13: =$D13&"" -> 口座の凍結についての確認書 | B13: =IF($F13="","","□") -> □ | C13: ⑸ | D13: 口座の凍結についての確認書 | E13: =IFERROR(VLOOKUP($D13,基本情報入力!AA$72:AB$109,2,FALSE),"") -> 記載の通りにご対応のうえ、ご返送願います。 | F13: {=_xlfn.IFS($D13="委任状",基本情報入力!$B$17,$D13="","",TRUE,1)} -> 1 | G13: =IF($F13="","","通") -> 通
A14: =$D14&"" -> 不動産・金融機関情報一覧 | B14: =IF($F14="","","□") -> □ | C14: ⑹ | D14: 不動産・金融機関情報一覧 | E14: =IFERROR(VLOOKUP($D14,基本情報入力!AA$72:AB$109,2,FALSE),"") -> 弊社へご依頼いただく不動産と金融機関の一覧となります。もしもご依頼数に増減がある場合は、こちらの書面に追記願います。 | F14: {=_xlfn.IFS($D14="委任状",基本情報入力!$B$17,$D14="","",TRUE,1)} -> 1 | G14: =IF($F14="","","通") -> 通
A15: =$D15&"" -> 戸籍関係情報 | B15: =IF($F15="","","□") -> □ | C15: ⑺ | D15: 戸籍関係情報 | E15: =IFERROR(VLOOKUP($D15,基本情報入力!AA$72:AB$109,2,FALSE),"") -> わかる範囲でご記入願います。 ※ご住所、本籍地、筆頭者が不明の場合、通常より戸籍収集にお時間を要する場合がございますこと、予めご了承ください。 | F15: {=_xlfn.IFS($D15="委任状",基本情報入力!$B$17,$D15="","",TRUE,1)} -> 1 | G15: =IF($F15="","","通") -> 通
A16: =$D16&"" | B16: =IF($F16="","","□") | E16: =IFERROR(VLOOKUP($D16,基本情報入力!AA$72:AB$109,2,FALSE),"") | F16: {=_xlfn.IFS($D16="委任状",基本情報入力!$B$17,$D16="","",TRUE,1)} | G16: =IF($F16="","","通")
A17: =$D17&"" | B17: =IF($F17="","","□") | E17: =IFERROR(VLOOKUP($D17,基本情報入力!AA$72:AB$109,2,FALSE),"") | F17: {=_xlfn.IFS($D17="委任状",基本情報入力!$B$17,$D17="","",TRUE,1)} | G17: =IF($F17="","","通")
A18: =$D18&"" | B18: =IF($F18="","","□") | E18: =IFERROR(VLOOKUP($D18,基本情報入力!AA$72:AB$109,2,FALSE),"") | F18: {=_xlfn.IFS($D18="委任状",基本情報入力!$B$17,$D18="","",TRUE,1)} | G18: =IF($F18="","","通")
A19: =$D19&"" | B19: =IF($F19="","","□") | E19: =IFERROR(VLOOKUP($D19,基本情報入力!AA$72:AB$109,2,FALSE),"") | F19: {=_xlfn.IFS($D19="委任状",基本情報入力!$B$17,$D19="","",TRUE,1)} | G19: =IF($F19="","","通")
B20: ⒉ ご準備のうえ、ご返送いただきたい書類
B21: ☑ | C21: 名称 | E21: 詳細 | F21: 返送 通数
A22: {=_xlfn._xlws.FILTER(基本情報入力!$R$22:$R$26,基本情報入力!$Q$22:$Q$26,"")} -> 印鑑証明書（原本） | B22: =IF($F22="","","□") -> □ | C22: =A22&"" -> 印鑑証明書（原本） | E22: =IFERROR(VLOOKUP($C22,基本情報入力!AC$72:AD$109,2,FALSE),"") -> 様の約1ヵ月以内に発行した印鑑証明書を右記通数ご返送願います。※マイナンバーカードがあれば、コンビニ取得可能です | F22: {=_xlfn.IFS($C22=基本情報入力!$AC$72,基本情報入力!$B$18,$C22="","",$C22=基本情報入力!AC$75,"各1",$C22=基本情報入力!$AC$76,"すべて",$C22=基本情報入力!$AC$78,基本情報入力!$B$18,TRUE,1)} -> 0 | G22: {=_xlfn.IFS($F22="","",$F22="すべて","",TRUE,"通")} -> 通
B23: =IF($F23="","","□") | C23: =A23&"" | E23: =IFERROR(VLOOKUP($C23,基本情報入力!AC$72:AD$109,2,FALSE),"") | F23: {=_xlfn.IFS($C23=基本情報入力!$AC$72,基本情報入力!$B$18,$C23="","",$C23=基本情報入力!AC$75,"各1",$C23=基本情報入力!$AC$76,"すべて",$C23=基本情報入力!$AC$78,基本情報入力!$B$18,TRUE,1)} | G23: {=_xlfn.IFS($F23="","",$F23="すべて","",TRUE,"通")}
B24: =IF($F24="","","□") | C24: =A24&"" | E24: =IFERROR(VLOOKUP($C24,基本情報入力!AC$72:AD$109,2,FALSE),"") | F24: {=_xlfn.IFS($C24=基本情報入力!$AC$72,基本情報入力!$B$18,$C24="","",$C24=基本情報入力!AC$75,"各1",$C24=基本情報入力!$AC$76,"すべて",$C24=基本情報入力!$AC$78,基本情報入力!$B$18,TRUE,1)} | G24: {=_xlfn.IFS($F24="","",$F24="すべて","",TRUE,"通")}
B25: =IF($F25="","","□") | C25: =A25&"" | E25: =IFERROR(VLOOKUP($C25,基本情報入力!AC$72:AD$109,2,FALSE),"") | F25: {=_xlfn.IFS($C25=基本情報入力!$AC$72,基本情報入力!$B$18,$C25="","",$C25=基本情報入力!AC$75,"各1",$C25=基本情報入力!$AC$76,"すべて",$C25=基本情報入力!$AC$78,基本情報入力!$B$18,TRUE,1)} | G25: {=_xlfn.IFS($F25="","",$F25="すべて","",TRUE,"通")}
B26: =IF($F26="","","□") | C26: =A26&"" | E26: =IFERROR(VLOOKUP($C26,基本情報入力!AC$72:AD$109,2,FALSE),"") | F26: {=_xlfn.IFS($C26=基本情報入力!$AC$72,基本情報入力!$B$18,$C26="","",$C26=基本情報入力!AC$75,"各1",$C26=基本情報入力!$AC$76,"すべて",$C26=基本情報入力!$AC$78,基本情報入力!$B$18,TRUE,1)} | G26: {=_xlfn.IFS($F26="","",$F26="すべて","",TRUE,"通")}

Sheet 委任状
J1: =IFERROR(VLOOKUP($D$2,送付状!$B$18:$O$28,2,FALSE),"") -> ⑷
D2: 委任状
A4: 主たる事務所所在 | E4: =基本情報入力!$P72&"" -> 東京都中央区八重洲1-7-20 | I4: =基本情報入力!$R72&"" -> 03-6868-8328
A5: 従たる事務所所在 | E5: =基本情報入力!$P73&"" -> 東京都新宿区西新宿2-7-1 | I5: =基本情報入力!$R73&"" -> 03-6868-8941
E6: =基本情報入力!$P74&"" -> 神奈川県横浜市神奈川区鶴屋町2-12-5 | I6: =基本情報入力!$R74&"" -> 045-550-4249
E7: =基本情報入力!$P75&"" -> 愛知県名古屋市中区栄3-2-3 | I7: =基本情報入力!$R75&"" -> 052-766-5024
E8: =基本情報入力!$P76&"" -> 大阪府大阪市北区中之島2-2-2 | I8: =基本情報入力!$R76&"" -> 06-7878-4155
A10: 名称 | D10: 行政書士法人チェスター
A11: 代表社員 | D11: =基本情報入力!I72 -> 清水茜作
A12: 行政書士 | D12: =_xlfn.CONCAT(基本情報入力!$J$72:$J$175) -> 浅倉貴行 西田竜介 藤本義昌 石川綾子 吉田幸寛 金井佑介 布施祐太郎 栗原大輔 石井祐貴 柴田彩香 松本拓弥 森町翼 中島絵里 小島文子 福岡なつみ 原山裕規
A14: 補助者 | D14: =_xlfn.CONCAT(基本情報入力!$K$72:$K$171) -> 池田絢音 増田千尋 川原千里 山崎宇紗子 君島絵梨 青柳由里子 山口知代 増田波輝 佐竹彩 佐野雅絵 宮城明香 丸山慧子 森中絵梨佳 東三条佑圭梨 小森和正 米田由香 菊川智恵子 宇野綾華 南香南江 土田修平 亀岡菜摘 白金大翔 三宅真莉奈 梅田奈央 芦田昭子 安西伽奈美 宮持玲那 進藤莉花 司馬里美 辻充代 植田愛望 土居八千代
A17: 上記の者を 遺産整理受任者 に選任し、被相続人 | G17: =基本情報入力!$C$23&"" | H17: の相続財産の承継に関して必要な
A18: 下記事務他一切の事務を処理する権限を委任します。
A20: 委任事項の内容
A21: ① | B21: 被相続人作成の遺言の有無の調査、遺言公正証書の謄本の請求及び受領に関する一切の件
A22: ② | B22: 官公署に対する諸手続、その他戸籍・除籍・原戸籍・戸籍の附票（本籍・筆頭者記載）、住民票（本籍・筆頭者・世帯主・続柄記載）、固定資産税評価証明書・固定資産名寄台帳の写し・農地基本台帳等（単有及び共有する全ての物件について）の申請並びに受領に関する一切の件
A25: ③ | B25: 今般相続手続に必要となる、遺産分割協議書、申請書、財産目録、遺産配分に関する説明書、その他一切の書類作成
A27: ④ | B27: 金融機関、ゆうちょ銀行、証券会社、保険会社、かんぽ生命その他法人等に対する、現存照会または取引履歴・入出金照会、残高証明の請求及び受領、各種書類または証書類の提出および受領、預貯金の解約、被相続人が行っていた契約（契約に類する約定を含む）の承継・変更・解約、貸金庫取引の解約並びに保管物の代表相続人への引渡、株式・有価証券等寄託物件の返還または相続移管並びに受渡、払戻金・満期金・株式配当金・出資金・保険金・還付金・給付金・売却代金等の請求、連絡、照会、その他預貯金・生命保険・株式・有価証券類の一切の相続手続
A32: ⑤ | B32: 相続人が行なうべき前各号の事務について必要な調査ならびに助言
A33: ⑥ | B33: その他、相続財産の承継のため必要な一切の事務
A34: ⑦ | B34: 上記被相続人の法定相続情報一覧図の作成、保管、交付、再交付の申し出及び受領に関する一切の件 尚、上記法定相続情報の利用目的は、登記申請及び預金払戻手続きであり、必要な写しの通数は10通
A36: ⑧ | B36: 証券保管振替機構に対する、上記被相続人及び私の登録済加入者情報に関する開示請求及びその情報を記載した「登録済加入者情報通知書」の受領等に係る一切の件
A38: ⑨ | B38: 前各号の事務処理を行うために必要とされる復代理人選任に関する一切の件
A39: ⑩ | B39: 本状及び添付書類の還付請求並びにその受領に関する一切の件
A41: =IF(基本情報入力!$D$12="","令和 年 月 日",基本情報入力!$D$12) -> 令和 年 月 日
A43: 住所 | D43: =基本情報入力!$H$24&""
D44: =基本情報入力!$I$24&""
A45: 氏名
D47: =基本情報入力!$C$24&" 様" -> 様

Sheet 口座凍結確認書
A1: 口座の凍結についての確認書 | K1: =IFERROR(VLOOKUP($A$1,送付状!$B$18:$O$28,2,FALSE),"") -> ⑸
D2: =基本情報入力!$C$23&"" | E2: 様 名義の口座について
A4: ⒈ | C4: 口座凍結の確認事項
C5: 以下の事項をご確認いただけましたら、□ にチェック（✔）をご記入ください。
C6: □ | D6: 口座凍結を行うと、すべてのお取引が停止します。
C7: □ | D7: 各種お支払いのお引き落とし口座に指定されている場合は、お引き落とし口座の変更のお手続きが必要となります。
C9: □ | D9: 金融機関により通帳の記帳もできなくなる場合がございます。
C10: □ | D10: 貸金庫がある場合は貸金庫も凍結され、ご相続人様全員が署名捺印済みの当該金融機関所定の書類や、ご相続人様全員の印鑑証明書等を当該金融機関へご提出をいただくまでは、開扉できなくなります。
A15: ⒉ | C15: 口座凍結の時期
C16: 下記項目の①・②の中から該当する項目をお選びいただき、番号に〇をしてください。なお、②を選択される場合は口座凍結が可能となるお日にちをご記入ください。 ※口座凍結をするまで金融機関のお手続きが開始されません。
C20: 【証券口座凍結の時期】
C21: ① | D21: 口座を凍結して問題ありません。
C22: ② | D22: 年 月 日以降でしたら口座凍結して問題ありません。
C23: ※被相続人様が証券会社に口座をお持ちでない場合は記入不要です。 ※ファンドラップや信用取引等を行っている場合、凍結連絡のタイミングで決済される可能性があります。
C25: 【銀行口座凍結の時期】
C26: ① | D26: 口座を凍結して問題ありません。
C27: ② | D27: 年 月 日以降でしたら口座凍結して問題ありません。
C30: 上記の内容を承諾いたします。
C31: 令和 年 月 日
G32: 氏名
G33: 行政書士法人チェスター 御中

Sheet 不動産・金融機関一覧
A1: 不動産・金融機関情報一覧 | V1: =IFERROR(VLOOKUP($A$1,送付状!$B$18:$O$28,2,FALSE),"") -> ⑹
A2: =基本情報入力!$C$23&"" | S2: 様 お名義
A3: ⒈ ①～は弊社へ調査、証明書発行をご依頼いただきました不動産が存する市区町村の一覧となります。一覧のほかに被相続人が不動産を所有されていた可能性のある市区町村あればご記入願います。（調査する市区町村に登録されている被相続人の住所地が住民票や附票で確認できない場合や、調査したい不動産の所在が都道府県までしかわからない場合などは、調査は致しかねますことあらかじめご承知おきください。）
A7: ① | B7: =基本情報入力!$G$49&"" | I7: ④ | J7: =基本情報入力!$G$52&"" | Q7: ⑦ | R7: =基本情報入力!$G$55&""
A8: ② | B8: =基本情報入力!$G$50&"" | I8: ⑤ | J8: =基本情報入力!$G$53&"" | Q8: ⑧ | R8: =基本情報入力!$G$56&""
A9: ③ | B9: =基本情報入力!$G$51&"" | I9: ⑥ | J9: =基本情報入力!$G$54&"" | Q9: ⑨ | R9: =基本情報入力!$G$57&""
A11: ⒉ ①～は弊社へご依頼いただきました金融機関（銀行・証券会社）の一覧となります。下記(ア)(イ)(ウ)をご確認のうえご対応願います。 (ア)弊社へご依頼いただく金融機関に追加や変更がございましたら、その旨ご記入願います。 (イ)お手続きをスムーズに進めるため、わかる範囲で追記願います。 (ウ)税理士法人チェスターに通帳等金融機関に関する書類をご提出済みの場合、(イ)はご記入不要です。
A16: ①
A17: 金融機関 | E17: =基本情報入力!$B$49&""
A18: 支店 | E18: =基本情報入力!$C$49&""
A19: 種類 | E19: =基本情報入力!$D$49&""
A20: =IF(E17="ゆうちょ銀行","記号番号","口座番号") -> 口座番号 | E20: =基本情報入力!$E$49&""
A22: ②
A23: 金融機関 | E23: =基本情報入力!$B$50&""
A24: 支店 | E24: =基本情報入力!$C$50&""
A25: 種類 | E25: =基本情報入力!$D$50&""
A26: =IF(E23="ゆうちょ銀行","記号番号","口座番号") -> 口座番号 | E26: =基本情報入力!$E$50&""
A28: ③
A29: 金融機関 | E29: =基本情報入力!$B$51&""
A30: 支店 | E30: =基本情報入力!$C$51&""
A31: 種類 | E31: =基本情報入力!$D$51&""
A32: =IF(E29="ゆうちょ銀行","記号番号","口座番号") -> 口座番号 | E32: =基本情報入力!$E$51&""
A34: ④
A35: 金融機関 | E35: =基本情報入力!$B$52&""
A36: 支店 | E36: =基本情報入力!$C$52&""
A37: 種類 | E37: =基本情報入力!$D$52&""
A38: =IF(E35="ゆうちょ銀行","記号番号","口座番号") -> 口座番号 | E38: =基本情報入力!$E$52&""
A40: ⑤
A41: 金融機関 | E41: =基本情報入力!$B$53&""
A42: 支店 | E42: =基本情報入力!$C$53&""
A43: 種類 | E43: =基本情報入力!$D$53&""
A44: =IF(E41="ゆうちょ銀行","記号番号","口座番号") -> 口座番号 | E44: =基本情報入力!$E$53&""
A45: ⑥
A46: 金融機関 | E46: =基本情報入力!$B$54&""
A47: 支店 | E47: =基本情報入力!$C$54&""
A48: 種類 | E48: =基本情報入力!$D$54&""
A49: =IF(E46="ゆうちょ銀行","記号番号","口座番号") -> 口座番号 | E49: =基本情報入力!$E$54&""
A51: ⑦
A52: 金融機関 | E52: =基本情報入力!$B$55&""
A53: 支店 | E53: =基本情報入力!$C$55&""
...

Sheet 【税関与あり】戸籍関係情報
B1: 戸籍関係情報 | G1: =IFERROR(VLOOKUP($B$1,送付状!$B$18:$O$28,2,FALSE),"") -> ⑺
B3: 被相続人（亡くなられた方）に関する情報
B4: ふりがな | C4: =基本情報入力!$D$23&"" | D4: 生年月日 | G4: =IF(基本情報入力!E23=""," 年 月 日",基本情報入力!$E$23) -> 年 月 日
B5: お名前 | C5: =基本情報入力!$C$23&""
D6: TEL | G6: =基本情報入力!$J$23&""
B7: ご住所 | C7: =IF(基本情報入力!$G$23=0,"〒 -","〒"&基本情報入力!$G$23) -> 〒 - | D7: 住民票 世帯主 | E7: □ | F7: 住民票の世帯主は本人
C8: =基本情報入力!$H$23&" "&基本情報入力!$I$23&"" | E8: □ | F8: 本人以外（お名前： ）
B9: 本籍地 | C9: =基本情報入力!$K$23&"" | D9: 戸籍 筆頭者 | E9: □ | F9: 戸籍の筆頭者は本人
E10: □ | F10: 本人以外（お名前： ）
B12: 相続人①(代表)
B13: ふりがな | C13: =基本情報入力!$D$24&"" | D13: 被相続人との続柄 | G13: =基本情報入力!$B$24&""
B14: お名前 | C14: =基本情報入力!$C$24&"" | D14: 生年月日 | G14: =IF(基本情報入力!$E$24=""," 年 月 日",基本情報入力!$E$24) -> 年 月 日
B16: 本籍地 | C16: =基本情報入力!$K$24&"" | D16: 戸籍 筆頭者 | E16: □ | F16: 戸籍の筆頭者は本人
E17: □ | F17: 本人以外（お名前： ）
B19: 相続人②
B20: ふりがな | C20: =基本情報入力!$D$25&"" | D20: 被相続人との続柄 | G20: =基本情報入力!$B$25&""
B21: お名前 | C21: =基本情報入力!$C$25&"" | D21: 生年月日 | G21: =IF(基本情報入力!$E$25=""," 年 月 日",基本情報入力!$E$25) -> 年 月 日
B23: 本籍地 | C23: =基本情報入力!$K$25&"" | D23: 戸籍 筆頭者 | E23: □ | F23: 戸籍の筆頭者は本人
E24: □ | F24: 本人以外（お名前： ）
B26: 相続人③
B27: ふりがな | C27: =基本情報入力!$D$26&"" | D27: 被相続人との続柄 | G27: =基本情報入力!$B$26&""
B28: お名前 | C28: =基本情報入力!$C$26&"" | D28: 生年月日 | G28: =IF(基本情報入力!$E$26=""," 年 月 日",基本情報入力!$E$26) -> 年 月 日
B30: 本籍地 | C30: =基本情報入力!$K$26&"" | D30: 戸籍 筆頭者 | E30: □ | F30: 戸籍の筆頭者は本人
E31: □ | F31: 本人以外（お名前： ）
B32: 相続人④
B33: ふりがな | C33: =基本情報入力!$D$27&"" | D33: 被相続人との続柄 | G33: =基本情報入力!$B$27&""
B34: お名前 | C34: =基本情報入力!$C$27&"" | D34: 生年月日 | G34: =IF(基本情報入力!$E$27=""," 年 月 日",基本情報入力!$E$27) -> 年 月 日
B36: 本籍地 | C36: =基本情報入力!$K$27&"" | D36: 戸籍 筆頭者 | E36: □ | F36: 戸籍の筆頭者は本人
E37: □ | F37: 本人以外（お名前： ）
B39: 相続人⑤
B40: ふりがな | C40: =基本情報入力!$D$28&"" | D40: 被相続人との続柄 | G40: =基本情報入力!$B$28&""
B41: お名前 | C41: =基本情報入力!$C$28&"" | D41: 生年月日 | G41: =IF(基本情報入力!$E$28=""," 年 月 日",基本情報入力!$E$28) -> 年 月 日
B43: 本籍地 | C43: =基本情報入力!$K$28&"" | D43: 戸籍 筆頭者 | E43: □ | F43: 戸籍の筆頭者は本人
E44: □ | F44: 本人以外（お名前： ）
B46: 相続人⑥
B47: ふりがな | C47: =基本情報入力!$D$29&"" | D47: 被相続人との続柄 | G47: =基本情報入力!$B$29&""
B48: お名前 | C48: =基本情報入力!$C$29&"" | D48: 生年月日 | G48: =IF(基本情報入力!$E$29=""," 年 月 日",基本情報入力!$E$29) -> 年 月 日
B50: 本籍地 | C50: =基本情報入力!$K$29&"" | D50: 戸籍 筆頭者 | E50: □ | F50: 戸籍の筆頭者は本人
E51: □ | F51: 本人以外（お名前： ）
B53: 相続人⑦
...

Sheet 【税関与なし】相続人連絡先等一覧
B1: 相続人連絡先等一覧 | G1: =IFERROR(VLOOKUP($B$1,送付状!$B$18:$O$28,2,FALSE),"")
B3: 被相続人（亡くなられた方）に関する情報
B4: ふりがな | C4: =基本情報入力!$D$23&"" | D4: 生年月日 | G4: =IF(基本情報入力!$E$23=""," 年 月 日",基本情報入力!$E$23) -> 年 月 日
B5: お名前 | C5: =基本情報入力!$C$23&""
D6: TEL | G6: =基本情報入力!$J$23&""
B7: ご住所 | C7: =IF(基本情報入力!$G$23=0,"〒 -","〒"&基本情報入力!$G$23) -> 〒 - | D7: 住民票 世帯主 | E7: □ | F7: 住民票の世帯主は本人
C8: =基本情報入力!$H$23&" "&基本情報入力!$I$23&"" | E8: □ | F8: 本人以外（お名前： ）
B9: 本籍地 | C9: =基本情報入力!$K$23&"" | D9: 戸籍 筆頭者 | E9: □ | F9: 戸籍の筆頭者は本人
E10: □ | F10: 本人以外（お名前： ）
B12: 相続人①(代表)
B13: ふりがな | C13: =基本情報入力!$D$24&"" | D13: 被相続人との続柄 | G13: =基本情報入力!$B$24&""
B14: お名前 | C14: =基本情報入力!$C$24&""
D15: 生年月日 | G15: =IF(基本情報入力!$E$24=""," 年 月 日",基本情報入力!$E$24) -> 年 月 日
B16: ご住所 | C16: =IF(基本情報入力!$G$24=0,"〒 -","〒"&基本情報入力!$G$24) -> 〒 -
C17: =基本情報入力!$H$24&" "&基本情報入力!$I$24&""
B18: 本籍地 | C18: =基本情報入力!$K$24&"" | D18: 戸籍 筆頭者 | E18: □ | F18: 戸籍の筆頭者は本人
E19: □ | F19: 本人以外（お名前： ）
B21: 相続人②
B22: ふりがな | C22: =基本情報入力!$D$25&"" | D22: 被相続人との続柄 | G22: =基本情報入力!$B$25&""
B23: お名前 | C23: =基本情報入力!$C$25&""
D24: 生年月日 | G24: =IF(基本情報入力!$E$25=""," 年 月 日",基本情報入力!$E$25) -> 年 月 日
B25: ご住所 | C25: =IF(基本情報入力!$G$25=0,"〒 -","〒"&基本情報入力!$G$25) -> 〒 -
C26: =基本情報入力!$H$25&" "&基本情報入力!$I$25&""
B27: 本籍地 | C27: =基本情報入力!$K$25&"" | D27: 戸籍 筆頭者 | E27: □ | F27: 戸籍の筆頭者は本人
E28: □ | F28: 本人以外（お名前： ）
B30: 相続人③
B31: ふりがな | C31: =基本情報入力!$D$26&"" | D31: 被相続人との続柄 | G31: =基本情報入力!$B$26&""
B32: お名前 | C32: =基本情報入力!$C$26&""
D33: 生年月日 | G33: =IF(基本情報入力!$E$26=""," 年 月 日",基本情報入力!$E$26) -> 年 月 日
B34: ご住所 | C34: =IF(基本情報入力!$G$26=0,"〒 -","〒"&基本情報入力!$G$26) -> 〒 -
C35: =基本情報入力!$H$26&" "&基本情報入力!$I$26&""
B36: 本籍地 | C36: =基本情報入力!$K$26&"" | D36: 戸籍 筆頭者 | E36: □ | F36: 戸籍の筆頭者は本人
E37: □ | F37: 本人以外（お名前： ）
B38: 相続人④
B39: ふりがな | C39: =基本情報入力!$D$27&"" | D39: 被相続人との続柄 | G39: =基本情報入力!$B$27&""
B40: お名前 | C40: =基本情報入力!$C$27&""
D41: 生年月日 | G41: =IF(基本情報入力!$E$27=""," 年 月 日",基本情報入力!$E$27) -> 年 月 日
B42: ご住所 | C42: =IF(基本情報入力!$G$27=0,"〒 -","〒"&基本情報入力!$G$27) -> 〒 -
C43: =基本情報入力!$H$27&" "&基本情報入力!$I$27&""
B44: 本籍地 | C44: =基本情報入力!$K$27&"" | D44: 戸籍 筆頭者 | E44: □ | F44: 戸籍の筆頭者は本人
...

Sheet 請求方法ご案内(パックのみ)※大和以外
A1: 【ご請求方法に関するご案内】
A4: ご依頼いただきました遺産整理手続き 相続手続きサポートパックでは、３回に分けて請求書をお送りいたします。
A9: 例） | B9: =IF(OR(基本情報入力!$D$14="提携先（大和・セット割あり）",基本情報入力!$D$14="提携先（大和・セット割なし）"),"添付不可",IF(AND(基本情報入力!$B$11>=基本情報入力!$A$72,基本情報入力!$B$11<=基本情報入力!$A$74),基本情報入力!$B$11&"の場合",""))
A12: 【基本報酬】 | D12: 【ご請求のタイミング】
A13: =IFERROR(VLOOKUP(基本情報入力!$B$11,基本情報入力!$A$72:$E$176,2,FALSE),"")
D15: 行政書士
A16: =IFERROR(IF(AND(ISNUMBER($A$13),ISNUMBER($A$24)),$A$13-$A$24,""),"") | D16: 1回目
A17: 戸籍等収集 財産調査 口座解約 等 | D17: ご契約時に、基本報酬の半金として | G17: =IFERROR(VLOOKUP(基本情報入力!$B$11,基本情報入力!$A$72:$E$176,4,FALSE),"") | I17: を着手金としてご請求します。
D19: 2回目
D20: 手続完了後、登記報酬を除く基本報酬の残金 | H20: =IFERROR($A$16-$G$17,"") | J20: +実費+あれば加算料
D21: 金を最終金としてご請求します。(行政書士業務に係る実費と加算料金に限る)
K22: =IF(基本情報入力!$D$11="あり","※お値引き分は、残金請求時にご精算させていただきます。","")
D23: 司法書士
A24: =IFERROR(VLOOKUP(基本情報入力!$D$14,基本情報入力!$AF$72:$AG$176,2,FALSE),"") | D24: 3回目
A25: 不動産の登記 | D25: 登記の準備が整い次第、登記報酬として | G25: =$A$24 | I25: +実費+あれば加算料金をご
D26: 請求します。(司法書士業務に係る加算料金と実費に限る)
E27: ※2回目と3回目の請求は、進捗状況により前後します。
A30: ※税理士法人チェスターへ相続税申告をご依頼いただいている場合や、 司法書士、弁護士等に裁判所への申立手続、訴訟手続などをご依頼いただいている場合は、 上記サポートパック費用とは別途、税理士・司法書士・弁護士の報酬が発生いたします。
A35: 行政書士 | H35: 司法書士
A36: 〒103-0028 | H36: =IFERROR(VLOOKUP(基本情報入力!$D$9,基本情報入力!$T$72:$Z$95,3,FALSE),基本情報入力!$V$72) -> 103-0023
A37: 東京都中央区八重洲一丁目7番20号 | H37: =IFERROR(VLOOKUP(基本情報入力!$D$9,基本情報入力!$T$72:$Z$95,4,FALSE),基本情報入力!$W$72) -> 東京都中央区日本橋本町3‐2‐11
A38: 八重洲口会館2階 | H38: =IFERROR(VLOOKUP(基本情報入力!$D$9,基本情報入力!$T$72:$Z$95,5,FALSE),基本情報入力!$X$72) -> 井門日本橋本町ビル4階
A39: 行政書士法人チェスター | H39: =IFERROR(VLOOKUP(基本情報入力!$D$9,基本情報入力!$T$72:$Z$95,2,FALSE),基本情報入力!$U$72) -> 司法書士法人チェスター
A40: TEL(代表):03-6868-8328 | H40: =IFERROR(VLOOKUP(基本情報入力!$D$9,基本情報入力!$T$72:$Z$95,6,FALSE),基本情報入力!$Z$72) -> 03-6869-5163

Sheet 請求方法ご案内(パックのみ)※金額なし
A1: 【ご請求方法に関するご案内】
A4: ご依頼いただきました遺産整理手続き 相続手続きサポートパックでは、３回に分けて請求書をお送りいたします。
D9: 【ご請求のタイミング】
D14: 行政書士
A15: 行政書士業務 戸籍等収集 財産調査 口座解約 等 | D15: 2回目
D16: 行政書士業務完了後、着手金と司法書士業務分の基本報酬を除く残金+実費+あれば加算料金をご請求します。(行政書士業務に係る実費と加算料金に限る)
K18: =IF(基本情報入力!$D$11="あり","※お値引き分は、残金請求時にご精算させていただきます。","")
D19: 司法書士
A20: 司法書士業務 不動産の登記 等 | D20: 3回目
D21: 登記の準備が整い次第、司法書士業務分の基本報酬+実費+あれば加算料金をご請求します。(司法書士業務に係る加算料金と実費に限る)
E23: ※2回目と3回目の請求は、進捗状況により前後します。
A26: ※税理士法人チェスターへ相続税申告をご依頼いただいている場合や、 司法書士、弁護士等に裁判所への申立手続、訴訟手続などをご依頼いただいている場合は、 上記サポートパック費用とは別途、税理士・司法書士・弁護士の報酬が発生いたします。
A31: 行政書士 | H31: 司法書士
A32: 〒103-0028 | H32: =VLOOKUP(基本情報入力!$D$9,基本情報入力!$T$72:$Z$95,3,FALSE) -> #N/A
A33: 東京都中央区八重洲一丁目7番20号 | H33: =VLOOKUP(基本情報入力!$D$9,基本情報入力!$T$72:$Z$95,4,FALSE) -> #N/A
A34: 八重洲口会館2階 | H34: =VLOOKUP(基本情報入力!$D$9,基本情報入力!$T$72:$Z$95,5,FALSE) -> #N/A
A35: 行政書士法人チェスター | H35: =VLOOKUP(基本情報入力!$D$9,基本情報入力!$T$72:$Z$95,2,FALSE) -> #N/A
A36: TEL(代表):03-6868-8328 | H36: =VLOOKUP(基本情報入力!$D$9,基本情報入力!$T$72:$Z$95,6,FALSE) -> #N/A

Sheet 実費台紙
A1: レタパシール 貼付台紙 | I1: 案件番号 | N1: 顧客名 | W1: 被相続人名 | AG1: 案件種類 | AM1: 担当
I2: =基本情報入力!$B$9 -> 0 | N2: =基本情報入力!$B$10 -> 0 | W2: =基本情報入力!$C$23 -> 0 | AG2: =基本情報入力!$B$11 -> 0 | AM2: =基本情報入力!B13&"・"&基本情報入力!D13 -> ・
A5: 送付 | V5: 返送
